/*
 * To change this template, choose Tools | Templates
 * and open the template in the editor.
 */
package cr0s.WarpDrive;

import java.util.Random;
import net.minecraft.block.Block;
import net.minecraft.world.World;

/**
 *
 * @author user
 */
public class WorldGenStation {
    public WorldGenStation() { }
    
    public boolean generate(World world, Random rand, int i, int j, int k) {

        world.setBlock(i + 1, j + 0, k + 3, Block.stone.blockID);
        world.setBlock(i + 1, j + 0, k + 12, Block.stone.blockID);
        world.setBlock(i + 1, j + 1, k + 3, Block.stone.blockID);
        world.setBlock(i + 1, j + 1, k + 12, Block.stone.blockID);
        world.setBlock(i + 1, j + 2, k + 3, Block.stone.blockID);
        world.setBlock(i + 1, j + 2, k + 4, Block.stone.blockID);
        world.setBlock(i + 1, j + 2, k + 5, Block.stone.blockID);
        world.setBlock(i + 1, j + 2, k + 6, Block.stone.blockID);
        world.setBlock(i + 1, j + 2, k + 7, Block.dirt.blockID);
        world.setBlock(i + 1, j + 2, k + 8, Block.dirt.blockID);
        world.setBlock(i + 1, j + 2, k + 9, Block.stone.blockID);
        world.setBlock(i + 1, j + 2, k + 10, Block.stone.blockID);
        world.setBlock(i + 1, j + 2, k + 11, Block.stone.blockID);
        world.setBlock(i + 1, j + 2, k + 12, Block.stone.blockID);
        world.setBlock(i + 1, j + 3, k + 3, Block.stone.blockID);
        world.setBlock(i + 1, j + 3, k + 4, Block.stone.blockID);
        world.setBlock(i + 1, j + 3, k + 5, Block.stone.blockID);
        world.setBlock(i + 1, j + 3, k + 10, Block.stone.blockID);
        world.setBlock(i + 1, j + 3, k + 11, Block.stone.blockID);
        world.setBlock(i + 1, j + 3, k + 12, Block.stone.blockID);
        world.setBlock(i + 1, j + 4, k + 3, Block.stone.blockID);
        world.setBlock(i + 1, j + 4, k + 4, Block.stone.blockID);
        world.setBlock(i + 1, j + 4, k + 5, Block.stone.blockID);
        world.setBlock(i + 1, j + 4, k + 10, Block.stone.blockID);
        world.setBlock(i + 1, j + 4, k + 11, Block.stone.blockID);
        world.setBlock(i + 1, j + 4, k + 12, Block.stone.blockID);
        world.setBlock(i + 1, j + 5, k + 3, Block.stone.blockID);
        world.setBlock(i + 1, j + 5, k + 4, Block.glass.blockID);
        world.setBlock(i + 1, j + 5, k + 5, Block.stone.blockID);
        world.setBlock(i + 1, j + 5, k + 6, Block.stone.blockID);
        world.setBlock(i + 1, j + 5, k + 9, Block.stone.blockID);
        world.setBlock(i + 1, j + 5, k + 10, Block.stone.blockID);
        world.setBlock(i + 1, j + 5, k + 11, Block.glass.blockID);
        world.setBlock(i + 1, j + 5, k + 12, Block.stone.blockID);
        world.setBlock(i + 1, j + 6, k + 3, Block.stone.blockID);
        world.setBlock(i + 1, j + 6, k + 4, Block.glass.blockID);
        world.setBlock(i + 1, j + 6, k + 5, Block.glass.blockID);
        world.setBlock(i + 1, j + 6, k + 6, Block.stone.blockID);
        world.setBlock(i + 1, j + 6, k + 7, Block.stone.blockID);
        world.setBlock(i + 1, j + 6, k + 8, Block.stone.blockID);
        world.setBlock(i + 1, j + 6, k + 9, Block.stone.blockID);
        world.setBlock(i + 1, j + 6, k + 10, Block.glass.blockID);
        world.setBlock(i + 1, j + 6, k + 11, Block.glass.blockID);
        world.setBlock(i + 1, j + 6, k + 12, Block.stone.blockID);
        world.setBlock(i + 1, j + 7, k + 3, Block.stone.blockID);
        world.setBlock(i + 1, j + 7, k + 12, Block.stone.blockID);
        world.setBlock(i + 2, j + 0, k + 2, Block.stone.blockID);
        world.setBlock(i + 2, j + 0, k + 3, Block.stone.blockID);
        world.setBlock(i + 2, j + 0, k + 4, Block.stone.blockID);
        world.setBlock(i + 2, j + 0, k + 12, Block.stone.blockID);
        world.setBlock(i + 2, j + 0, k + 13, Block.stone.blockID);
        world.setBlock(i + 2, j + 1, k + 2, Block.stone.blockID);
        world.setBlock(i + 2, j + 1, k + 3, Block.stone.blockID);
        world.setBlock(i + 2, j + 1, k + 4, Block.stone.blockID);
        world.setBlock(i + 2, j + 1, k + 5, Block.stone.blockID);
        world.setBlock(i + 2, j + 1, k + 6, Block.stone.blockID);
        world.setBlock(i + 2, j + 1, k + 7, Block.stone.blockID);
        world.setBlock(i + 2, j + 1, k + 8, Block.stone.blockID);
        world.setBlock(i + 2, j + 1, k + 9, Block.stone.blockID);
        world.setBlock(i + 2, j + 1, k + 10, Block.stone.blockID);
        world.setBlock(i + 2, j + 1, k + 11, Block.stone.blockID);
        world.setBlock(i + 2, j + 1, k + 12, Block.stone.blockID);
        world.setBlock(i + 2, j + 1, k + 13, Block.stone.blockID);
        world.setBlock(i + 2, j + 2, k + 2, Block.stone.blockID);
        world.setBlock(i + 2, j + 2, k + 3, Block.stone.blockID);
        world.setBlock(i + 2, j + 2, k + 4, Block.stone.blockID);
        world.setBlock(i + 2, j + 2, k + 5, Block.stone.blockID);
        world.setBlock(i + 2, j + 2, k + 6, Block.stone.blockID);
        world.setBlock(i + 2, j + 2, k + 7, Block.stone.blockID);
        world.setBlock(i + 2, j + 2, k + 8, Block.stone.blockID);
        world.setBlock(i + 2, j + 2, k + 9, Block.stone.blockID);
        world.setBlock(i + 2, j + 2, k + 10, Block.stone.blockID);
        world.setBlock(i + 2, j + 2, k + 11, Block.stone.blockID);
        world.setBlock(i + 2, j + 2, k + 12, Block.stone.blockID);
        world.setBlock(i + 2, j + 2, k + 13, Block.stone.blockID);
        world.setBlock(i + 2, j + 3, k + 2, Block.stone.blockID);
        world.setBlock(i + 2, j + 3, k + 13, Block.stone.blockID);
        world.setBlock(i + 2, j + 4, k + 2, Block.stone.blockID);
        world.setBlock(i + 2, j + 4, k + 13, Block.stone.blockID);
        world.setBlock(i + 2, j + 5, k + 2, Block.stone.blockID);
        world.setBlock(i + 2, j + 5, k + 13, Block.stone.blockID);
        world.setBlock(i + 2, j + 6, k + 2, Block.stone.blockID);
        world.setBlock(i + 2, j + 6, k + 13, Block.stone.blockID);
        world.setBlock(i + 2, j + 7, k + 2, Block.stone.blockID);
        world.setBlock(i + 2, j + 7, k + 3, Block.stone.blockID);
        world.setBlock(i + 2, j + 7, k + 4, Block.stone.blockID);
        world.setBlock(i + 2, j + 7, k + 5, Block.stone.blockID);
        world.setBlock(i + 2, j + 7, k + 6, Block.glass.blockID);
        world.setBlock(i + 2, j + 7, k + 7, Block.glass.blockID);
        world.setBlock(i + 2, j + 7, k + 8, Block.glass.blockID);
        world.setBlock(i + 2, j + 7, k + 9, Block.glass.blockID);
        world.setBlock(i + 2, j + 7, k + 10, Block.glass.blockID);
        world.setBlock(i + 2, j + 7, k + 11, Block.stone.blockID);
        world.setBlock(i + 2, j + 7, k + 12, Block.stone.blockID);
        world.setBlock(i + 2, j + 7, k + 13, Block.stone.blockID);
        world.setBlock(i + 3, j + 0, k + 4, Block.stone.blockID);
        world.setBlock(i + 3, j + 0, k + 5, Block.stone.blockID);
        world.setBlock(i + 3, j + 0, k + 11, Block.stone.blockID);
        world.setBlock(i + 3, j + 0, k + 12, Block.stone.blockID);
        world.setBlock(i + 3, j + 1, k + 3, Block.stone.blockID);
        world.setBlock(i + 3, j + 1, k + 4, Block.stone.blockID);
        world.setBlock(i + 3, j + 1, k + 5, Block.stone.blockID);
        world.setBlock(i + 3, j + 1, k + 6, Block.stone.blockID);
        world.setBlock(i + 3, j + 1, k + 7, Block.stone.blockID);
        world.setBlock(i + 3, j + 1, k + 8, Block.stone.blockID);
        world.setBlock(i + 3, j + 1, k + 9, Block.stone.blockID);
        world.setBlock(i + 3, j + 1, k + 10, Block.stone.blockID);
        world.setBlock(i + 3, j + 1, k + 11, Block.stone.blockID);
        world.setBlock(i + 3, j + 1, k + 12, Block.stone.blockID);
        world.setBlock(i + 3, j + 2, k + 1, Block.stone.blockID);
        world.setBlock(i + 3, j + 2, k + 4, Block.stone.blockID);
        world.setBlock(i + 3, j + 2, k + 5, Block.stone.blockID);
        world.setBlock(i + 3, j + 2, k + 6, Block.stone.blockID);
        world.setBlock(i + 3, j + 2, k + 7, Block.stone.blockID);
        world.setBlock(i + 3, j + 2, k + 8, Block.stone.blockID);
        world.setBlock(i + 3, j + 2, k + 9, Block.stone.blockID);
        world.setBlock(i + 3, j + 2, k + 10, Block.stone.blockID);
        world.setBlock(i + 3, j + 2, k + 11, Block.stone.blockID);
        world.setBlock(i + 3, j + 2, k + 12, Block.stone.blockID);
        world.setBlock(i + 3, j + 2, k + 13, Block.stone.blockID);
        world.setBlock(i + 3, j + 3, k + 1, Block.stone.blockID);
        world.setBlock(i + 3, j + 3, k + 13, Block.chest.blockID, 2, 0);
        world.setBlock(i + 3, j + 3, k + 14, Block.stone.blockID);
        world.setBlock(i + 3, j + 4, k + 1, Block.stone.blockID);
        world.setBlock(i + 3, j + 4, k + 14, Block.stone.blockID);
        world.setBlock(i + 3, j + 5, k + 1, Block.stone.blockID);
        world.setBlock(i + 3, j + 5, k + 2, Block.dispenser.blockID, 3, 0);
        world.setBlock(i + 3, j + 5, k + 14, Block.stone.blockID);
        world.setBlock(i + 3, j + 6, k + 1, Block.stone.blockID);
        world.setBlock(i + 3, j + 6, k + 2, Block.planks.blockID);
        world.setBlock(i + 3, j + 6, k + 14, Block.stone.blockID);
        world.setBlock(i + 3, j + 7, k + 1, Block.stone.blockID);
        world.setBlock(i + 3, j + 7, k + 2, Block.blockLapis.blockID);
        world.setBlock(i + 3, j + 7, k + 3, Block.stone.blockID);
        world.setBlock(i + 3, j + 7, k + 4, Block.glowStone.blockID);
        world.setBlock(i + 3, j + 7, k + 5, Block.stone.blockID);
        world.setBlock(i + 3, j + 7, k + 6, Block.stone.blockID);
        world.setBlock(i + 3, j + 7, k + 7, Block.glass.blockID);
        world.setBlock(i + 3, j + 7, k + 8, Block.glass.blockID);
        world.setBlock(i + 3, j + 7, k + 9, Block.glass.blockID);
        world.setBlock(i + 3, j + 7, k + 10, Block.stone.blockID);
        world.setBlock(i + 3, j + 7, k + 11, Block.stone.blockID);
        world.setBlock(i + 3, j + 7, k + 12, Block.glowStone.blockID);
        world.setBlock(i + 3, j + 7, k + 13, Block.stone.blockID);
        world.setBlock(i + 3, j + 7, k + 14, Block.stone.blockID);
        world.setBlock(i + 3, j + 8, k + 2, Block.glass.blockID);
        world.setBlock(i + 3, j + 8, k + 4, Block.stone.blockID);
        world.setBlock(i + 3, j + 8, k + 12, Block.stone.blockID);
        world.setBlock(i + 4, j + 0, k + 5, Block.stone.blockID);
        world.setBlock(i + 4, j + 0, k + 6, Block.stone.blockID);
        world.setBlock(i + 4, j + 0, k + 10, Block.stone.blockID);
        world.setBlock(i + 4, j + 0, k + 11, Block.stone.blockID);
        world.setBlock(i + 4, j + 1, k + 3, Block.stone.blockID);
        world.setBlock(i + 4, j + 1, k + 4, Block.stone.blockID);
        world.setBlock(i + 4, j + 1, k + 5, Block.stone.blockID);
        world.setBlock(i + 4, j + 1, k + 6, Block.stone.blockID);
        world.setBlock(i + 4, j + 1, k + 7, Block.stone.blockID);
        world.setBlock(i + 4, j + 1, k + 8, Block.stone.blockID);
        world.setBlock(i + 4, j + 1, k + 9, Block.stone.blockID);
        world.setBlock(i + 4, j + 1, k + 10, Block.stone.blockID);
        world.setBlock(i + 4, j + 1, k + 11, Block.stone.blockID);
        world.setBlock(i + 4, j + 1, k + 12, Block.stone.blockID);
        world.setBlock(i + 4, j + 2, k + 2, Block.stone.blockID);
        world.setBlock(i + 4, j + 2, k + 4, Block.stone.blockID);
        world.setBlock(i + 4, j + 2, k + 5, Block.stone.blockID);
        world.setBlock(i + 4, j + 2, k + 6, Block.stone.blockID);
        world.setBlock(i + 4, j + 2, k + 7, Block.stone.blockID);
        world.setBlock(i + 4, j + 2, k + 8, Block.stone.blockID);
        world.setBlock(i + 4, j + 2, k + 9, Block.stone.blockID);
        world.setBlock(i + 4, j + 2, k + 10, Block.stone.blockID);
        world.setBlock(i + 4, j + 2, k + 11, Block.stone.blockID);
        world.setBlock(i + 4, j + 2, k + 12, Block.stone.blockID);
        world.setBlock(i + 4, j + 2, k + 13, Block.stone.blockID);
        world.setBlock(i + 4, j + 3, k + 1, Block.stone.blockID);
        world.setBlock(i + 4, j + 3, k + 13, Block.chest.blockID, 2, 0);
        world.setBlock(i + 4, j + 3, k + 14, Block.stone.blockID);
        world.setBlock(i + 4, j + 4, k + 1, Block.glass.blockID);
        world.setBlock(i + 4, j + 4, k + 14, Block.glass.blockID);
        world.setBlock(i + 4, j + 5, k + 1, Block.glass.blockID);
        world.setBlock(i + 4, j + 5, k + 14, Block.glass.blockID);
        world.setBlock(i + 4, j + 6, k + 1, Block.stone.blockID);
        world.setBlock(i + 4, j + 6, k + 2, Block.planks.blockID);
        world.setBlock(i + 4, j + 6, k + 14, Block.stone.blockID);
        world.setBlock(i + 4, j + 7, k + 1, Block.glass.blockID);
        world.setBlock(i + 4, j + 7, k + 2, Block.blockLapis.blockID);
        world.setBlock(i + 4, j + 7, k + 3, Block.stone.blockID);
        world.setBlock(i + 4, j + 7, k + 4, Block.stone.blockID);
        world.setBlock(i + 4, j + 7, k + 5, Block.glowStone.blockID);
        world.setBlock(i + 4, j + 7, k + 6, Block.stone.blockID);
        world.setBlock(i + 4, j + 7, k + 7, Block.stone.blockID);
        world.setBlock(i + 4, j + 7, k + 8, Block.glass.blockID);
        world.setBlock(i + 4, j + 7, k + 9, Block.stone.blockID);
        world.setBlock(i + 4, j + 7, k + 10, Block.stone.blockID);
        world.setBlock(i + 4, j + 7, k + 11, Block.glowStone.blockID);
        world.setBlock(i + 4, j + 7, k + 12, Block.stone.blockID);
        world.setBlock(i + 4, j + 7, k + 13, Block.stone.blockID);
        world.setBlock(i + 4, j + 8, k + 2, Block.glass.blockID);
        world.setBlock(i + 4, j + 8, k + 5, Block.stone.blockID);
        world.setBlock(i + 4, j + 8, k + 11, Block.stone.blockID);
        world.setBlock(i + 5, j + 0, k + 6, Block.stone.blockID);
        world.setBlock(i + 5, j + 0, k + 7, Block.stone.blockID);
        world.setBlock(i + 5, j + 0, k + 9, Block.stone.blockID);
        world.setBlock(i + 5, j + 0, k + 10, Block.stone.blockID);
        world.setBlock(i + 5, j + 1, k + 3, Block.stone.blockID);
        world.setBlock(i + 5, j + 1, k + 4, Block.stone.blockID);
        world.setBlock(i + 5, j + 1, k + 5, Block.stone.blockID);
        world.setBlock(i + 5, j + 1, k + 6, Block.stone.blockID);
        world.setBlock(i + 5, j + 1, k + 7, Block.stone.blockID);
        world.setBlock(i + 5, j + 1, k + 8, Block.stone.blockID);
        world.setBlock(i + 5, j + 1, k + 9, Block.stone.blockID);
        world.setBlock(i + 5, j + 1, k + 10, Block.stone.blockID);
        world.setBlock(i + 5, j + 1, k + 11, Block.stone.blockID);
        world.setBlock(i + 5, j + 1, k + 12, Block.stone.blockID);
        world.setBlock(i + 5, j + 2, k + 2, Block.stone.blockID);
        world.setBlock(i + 5, j + 2, k + 4, Block.stone.blockID);
        world.setBlock(i + 5, j + 2, k + 5, Block.stone.blockID);
        world.setBlock(i + 5, j + 2, k + 6, Block.stone.blockID);
        world.setBlock(i + 5, j + 2, k + 7, Block.stone.blockID);
        world.setBlock(i + 5, j + 2, k + 8, Block.stone.blockID);
        world.setBlock(i + 5, j + 2, k + 9, Block.stone.blockID);
        world.setBlock(i + 5, j + 2, k + 10, Block.stone.blockID);
        world.setBlock(i + 5, j + 2, k + 11, Block.stone.blockID);
        world.setBlock(i + 5, j + 2, k + 12, Block.stone.blockID);
        world.setBlock(i + 5, j + 2, k + 13, Block.stone.blockID);
        world.setBlock(i + 5, j + 3, k + 1, Block.stone.blockID);
        world.setBlock(i + 5, j + 3, k + 14, Block.stone.blockID);
        world.setBlock(i + 5, j + 4, k + 1, Block.glass.blockID);
        world.setBlock(i + 5, j + 4, k + 14, Block.glass.blockID);
        world.setBlock(i + 5, j + 5, k + 1, Block.glass.blockID);
        world.setBlock(i + 5, j + 5, k + 14, Block.glass.blockID);
        world.setBlock(i + 5, j + 6, k + 1, Block.stone.blockID);
        world.setBlock(i + 5, j + 6, k + 2, Block.planks.blockID);
        world.setBlock(i + 5, j + 6, k + 14, Block.stone.blockID);
        world.setBlock(i + 5, j + 7, k + 1, Block.glass.blockID);
        world.setBlock(i + 5, j + 7, k + 2, Block.blockLapis.blockID);
        world.setBlock(i + 5, j + 7, k + 3, Block.glass.blockID);
        world.setBlock(i + 5, j + 7, k + 4, Block.stone.blockID);
        world.setBlock(i + 5, j + 7, k + 5, Block.stone.blockID);
        world.setBlock(i + 5, j + 7, k + 6, Block.stone.blockID);
        world.setBlock(i + 5, j + 7, k + 7, Block.stone.blockID);
        world.setBlock(i + 5, j + 7, k + 8, Block.stone.blockID);
        world.setBlock(i + 5, j + 7, k + 9, Block.glowStone.blockID);
        world.setBlock(i + 5, j + 7, k + 10, Block.glowStone.blockID);
        world.setBlock(i + 5, j + 7, k + 11, Block.stone.blockID);
        world.setBlock(i + 5, j + 7, k + 12, Block.stone.blockID);
        world.setBlock(i + 5, j + 7, k + 13, Block.glass.blockID);
        world.setBlock(i + 5, j + 8, k + 2, Block.glass.blockID);
        world.setBlock(i + 5, j + 8, k + 9, Block.stone.blockID);
        world.setBlock(i + 5, j + 8, k + 10, Block.stone.blockID);
        world.setBlock(i + 6, j + 0, k + 7, Block.stone.blockID);
        world.setBlock(i + 6, j + 0, k + 8, Block.stone.blockID);
        world.setBlock(i + 6, j + 1, k + 3, Block.stone.blockID);
        world.setBlock(i + 6, j + 1, k + 4, Block.stone.blockID);
        world.setBlock(i + 6, j + 1, k + 5, Block.stone.blockID);
        world.setBlock(i + 6, j + 1, k + 6, Block.stone.blockID);
        world.setBlock(i + 6, j + 1, k + 7, Block.stone.blockID);
        world.setBlock(i + 6, j + 1, k + 8, Block.stone.blockID);
        world.setBlock(i + 6, j + 1, k + 9, Block.stone.blockID);
        world.setBlock(i + 6, j + 1, k + 10, Block.stone.blockID);
        world.setBlock(i + 6, j + 1, k + 11, Block.stone.blockID);
        world.setBlock(i + 6, j + 1, k + 12, Block.stone.blockID);
        world.setBlock(i + 6, j + 2, k + 2, Block.stone.blockID);
        world.setBlock(i + 6, j + 2, k + 4, Block.stone.blockID);
        world.setBlock(i + 6, j + 2, k + 5, Block.stone.blockID);
        world.setBlock(i + 6, j + 2, k + 6, Block.stone.blockID);
        world.setBlock(i + 6, j + 2, k + 7, Block.stone.blockID);
        world.setBlock(i + 6, j + 2, k + 8, Block.stone.blockID);
        world.setBlock(i + 6, j + 2, k + 9, Block.stone.blockID);
        world.setBlock(i + 6, j + 2, k + 10, Block.stone.blockID);
        world.setBlock(i + 6, j + 2, k + 11, Block.stone.blockID);
        world.setBlock(i + 6, j + 2, k + 12, Block.stone.blockID);
        world.setBlock(i + 6, j + 2, k + 13, Block.stone.blockID);
        world.setBlock(i + 6, j + 3, k + 1, Block.stone.blockID);
        world.setBlock(i + 6, j + 3, k + 13, Block.chest.blockID, 2, 0);
        world.setBlock(i + 6, j + 3, k + 14, Block.stone.blockID);
        world.setBlock(i + 6, j + 4, k + 1, Block.glass.blockID);
        world.setBlock(i + 6, j + 4, k + 14, Block.glass.blockID);
        world.setBlock(i + 6, j + 5, k + 1, Block.glass.blockID);
        world.setBlock(i + 6, j + 5, k + 14, Block.glass.blockID);
        world.setBlock(i + 6, j + 6, k + 1, Block.stone.blockID);
        world.setBlock(i + 6, j + 6, k + 2, Block.planks.blockID);
        world.setBlock(i + 6, j + 6, k + 14, Block.stone.blockID);
        world.setBlock(i + 6, j + 7, k + 1, Block.glass.blockID);
        world.setBlock(i + 6, j + 7, k + 2, Block.blockLapis.blockID);
        world.setBlock(i + 6, j + 7, k + 3, Block.glass.blockID);
        world.setBlock(i + 6, j + 7, k + 4, Block.glass.blockID);
        world.setBlock(i + 6, j + 7, k + 5, Block.stone.blockID);
        world.setBlock(i + 6, j + 7, k + 6, Block.stone.blockID);
        world.setBlock(i + 6, j + 7, k + 7, Block.glowStone.blockID);
        world.setBlock(i + 6, j + 7, k + 8, Block.stone.blockID);
        world.setBlock(i + 6, j + 7, k + 9, Block.stone.blockID);
        world.setBlock(i + 6, j + 7, k + 10, Block.glowStone.blockID);
        world.setBlock(i + 6, j + 7, k + 11, Block.stone.blockID);
        world.setBlock(i + 6, j + 7, k + 12, Block.glass.blockID);
        world.setBlock(i + 6, j + 7, k + 13, Block.glass.blockID);
        world.setBlock(i + 6, j + 8, k + 2, Block.glass.blockID);
        world.setBlock(i + 6, j + 8, k + 7, Block.stone.blockID);
        world.setBlock(i + 6, j + 8, k + 10, Block.stone.blockID);
        world.setBlock(i + 7, j + 0, k + 7, Block.stone.blockID);
        world.setBlock(i + 7, j + 0, k + 8, Block.stone.blockID);
        world.setBlock(i + 7, j + 0, k + 9, Block.stone.blockID);
        world.setBlock(i + 7, j + 1, k + 3, Block.stone.blockID);
        world.setBlock(i + 7, j + 1, k + 4, Block.stone.blockID);
        world.setBlock(i + 7, j + 1, k + 5, Block.stone.blockID);
        world.setBlock(i + 7, j + 1, k + 6, Block.stone.blockID);
        world.setBlock(i + 7, j + 1, k + 7, Block.stone.blockID);
        world.setBlock(i + 7, j + 1, k + 8, Block.stone.blockID);
        world.setBlock(i + 7, j + 1, k + 9, Block.stone.blockID);
        world.setBlock(i + 7, j + 1, k + 10, Block.stone.blockID);
        world.setBlock(i + 7, j + 1, k + 11, Block.stone.blockID);
        world.setBlock(i + 7, j + 1, k + 12, Block.stone.blockID);
        world.setBlock(i + 7, j + 2, k + 2, Block.stone.blockID);
        world.setBlock(i + 7, j + 2, k + 4, Block.stone.blockID);
        world.setBlock(i + 7, j + 2, k + 5, Block.stone.blockID);
        world.setBlock(i + 7, j + 2, k + 6, Block.stone.blockID);
        world.setBlock(i + 7, j + 2, k + 7, Block.stone.blockID);
        world.setBlock(i + 7, j + 2, k + 8, Block.stone.blockID);
        world.setBlock(i + 7, j + 2, k + 9, Block.stone.blockID);
        world.setBlock(i + 7, j + 2, k + 10, Block.stone.blockID);
        world.setBlock(i + 7, j + 2, k + 11, Block.stone.blockID);
        world.setBlock(i + 7, j + 2, k + 12, Block.stone.blockID);
        world.setBlock(i + 7, j + 2, k + 13, Block.stone.blockID);
        world.setBlock(i + 7, j + 3, k + 1, Block.stone.blockID);
        world.setBlock(i + 7, j + 3, k + 13, Block.chest.blockID, 2, 0);
        world.setBlock(i + 7, j + 3, k + 14, Block.stone.blockID);
        world.setBlock(i + 7, j + 4, k + 1, Block.glass.blockID);
        world.setBlock(i + 7, j + 4, k + 14, Block.glass.blockID);
        world.setBlock(i + 7, j + 5, k + 1, Block.glass.blockID);
        world.setBlock(i + 7, j + 5, k + 14, Block.glass.blockID);
        world.setBlock(i + 7, j + 6, k + 1, Block.stone.blockID);
        world.setBlock(i + 7, j + 6, k + 2, Block.planks.blockID);
        world.setBlock(i + 7, j + 6, k + 14, Block.stone.blockID);
        world.setBlock(i + 7, j + 7, k + 1, Block.glass.blockID);
        world.setBlock(i + 7, j + 7, k + 2, Block.blockLapis.blockID);
        world.setBlock(i + 7, j + 7, k + 3, Block.glass.blockID);
        world.setBlock(i + 7, j + 7, k + 4, Block.stone.blockID);
        world.setBlock(i + 7, j + 7, k + 5, Block.glowStone.blockID);
        world.setBlock(i + 7, j + 7, k + 6, Block.stone.blockID);
        world.setBlock(i + 7, j + 7, k + 7, Block.stone.blockID);
        world.setBlock(i + 7, j + 7, k + 8, Block.glowStone.blockID);
        world.setBlock(i + 7, j + 7, k + 9, Block.stone.blockID);
        world.setBlock(i + 7, j + 7, k + 10, Block.stone.blockID);
        world.setBlock(i + 7, j + 7, k + 11, Block.glass.blockID);
        world.setBlock(i + 7, j + 7, k + 12, Block.glass.blockID);
        world.setBlock(i + 7, j + 7, k + 13, Block.glass.blockID);
        world.setBlock(i + 7, j + 8, k + 2, Block.glass.blockID);
        world.setBlock(i + 7, j + 8, k + 5, Block.stone.blockID);
        world.setBlock(i + 7, j + 8, k + 8, Block.stone.blockID);
        world.setBlock(i + 8, j + 0, k + 6, Block.stone.blockID);
        world.setBlock(i + 8, j + 0, k + 7, Block.stone.blockID);
        world.setBlock(i + 8, j + 0, k + 9, Block.stone.blockID);
        world.setBlock(i + 8, j + 0, k + 10, Block.stone.blockID);
        world.setBlock(i + 8, j + 1, k + 3, Block.stone.blockID);
        world.setBlock(i + 8, j + 1, k + 4, Block.stone.blockID);
        world.setBlock(i + 8, j + 1, k + 5, Block.stone.blockID);
        world.setBlock(i + 8, j + 1, k + 6, Block.stone.blockID);
        world.setBlock(i + 8, j + 1, k + 7, Block.stone.blockID);
        world.setBlock(i + 8, j + 1, k + 8, Block.stone.blockID);
        world.setBlock(i + 8, j + 1, k + 9, Block.stone.blockID);
        world.setBlock(i + 8, j + 1, k + 10, Block.stone.blockID);
        world.setBlock(i + 8, j + 1, k + 11, Block.stone.blockID);
        world.setBlock(i + 8, j + 1, k + 12, Block.stone.blockID);
        world.setBlock(i + 8, j + 2, k + 2, Block.stone.blockID);
        world.setBlock(i + 8, j + 2, k + 4, Block.stone.blockID);
        world.setBlock(i + 8, j + 2, k + 5, Block.stone.blockID);
        world.setBlock(i + 8, j + 2, k + 6, Block.stone.blockID);
        world.setBlock(i + 8, j + 2, k + 7, Block.stone.blockID);
        world.setBlock(i + 8, j + 2, k + 8, Block.stone.blockID);
        world.setBlock(i + 8, j + 2, k + 9, Block.stone.blockID);
        world.setBlock(i + 8, j + 2, k + 10, Block.stone.blockID);
        world.setBlock(i + 8, j + 2, k + 11, Block.stone.blockID);
        world.setBlock(i + 8, j + 2, k + 12, Block.stone.blockID);
        world.setBlock(i + 8, j + 2, k + 13, Block.stone.blockID);
        world.setBlock(i + 8, j + 3, k + 1, Block.stone.blockID);
        world.setBlock(i + 8, j + 3, k + 14, Block.stone.blockID);
        world.setBlock(i + 8, j + 4, k + 1, Block.glass.blockID);
        world.setBlock(i + 8, j + 4, k + 14, Block.glass.blockID);
        world.setBlock(i + 8, j + 5, k + 1, Block.glass.blockID);
        world.setBlock(i + 8, j + 5, k + 14, Block.glass.blockID);
        world.setBlock(i + 8, j + 6, k + 1, Block.stone.blockID);
        world.setBlock(i + 8, j + 6, k + 2, Block.planks.blockID);
        world.setBlock(i + 8, j + 6, k + 14, Block.stone.blockID);
        world.setBlock(i + 8, j + 7, k + 1, Block.glass.blockID);
        world.setBlock(i + 8, j + 7, k + 2, Block.blockLapis.blockID);
        world.setBlock(i + 8, j + 7, k + 3, Block.stone.blockID);
        world.setBlock(i + 8, j + 7, k + 4, Block.stone.blockID);
        world.setBlock(i + 8, j + 7, k + 5, Block.glowStone.blockID);
        world.setBlock(i + 8, j + 7, k + 6, Block.glowStone.blockID);
        world.setBlock(i + 8, j + 7, k + 7, Block.stone.blockID);
        world.setBlock(i + 8, j + 7, k + 8, Block.stone.blockID);
        world.setBlock(i + 8, j + 7, k + 9, Block.stone.blockID);
        world.setBlock(i + 8, j + 7, k + 10, Block.stone.blockID);
        world.setBlock(i + 8, j + 7, k + 11, Block.stone.blockID);
        world.setBlock(i + 8, j + 7, k + 12, Block.glass.blockID);
        world.setBlock(i + 8, j + 7, k + 13, Block.glass.blockID);
        world.setBlock(i + 8, j + 8, k + 2, Block.glass.blockID);
        world.setBlock(i + 8, j + 8, k + 5, Block.stone.blockID);
        world.setBlock(i + 8, j + 8, k + 6, Block.stone.blockID);
        world.setBlock(i + 9, j + 0, k + 5, Block.stone.blockID);
        world.setBlock(i + 9, j + 0, k + 6, Block.stone.blockID);
        world.setBlock(i + 9, j + 0, k + 10, Block.stone.blockID);
        world.setBlock(i + 9, j + 0, k + 11, Block.stone.blockID);
        world.setBlock(i + 9, j + 1, k + 3, Block.stone.blockID);
        world.setBlock(i + 9, j + 1, k + 4, Block.stone.blockID);
        world.setBlock(i + 9, j + 1, k + 5, Block.stone.blockID);
        world.setBlock(i + 9, j + 1, k + 6, Block.stone.blockID);
        world.setBlock(i + 9, j + 1, k + 7, Block.stone.blockID);
        world.setBlock(i + 9, j + 1, k + 8, Block.stone.blockID);
        world.setBlock(i + 9, j + 1, k + 9, Block.stone.blockID);
        world.setBlock(i + 9, j + 1, k + 10, Block.stone.blockID);
        world.setBlock(i + 9, j + 1, k + 11, Block.stone.blockID);
        world.setBlock(i + 9, j + 1, k + 12, Block.stone.blockID);
        world.setBlock(i + 9, j + 2, k + 2, Block.stone.blockID);
        world.setBlock(i + 9, j + 2, k + 4, Block.stone.blockID);
        world.setBlock(i + 9, j + 2, k + 5, Block.stone.blockID);
        world.setBlock(i + 9, j + 2, k + 6, Block.stone.blockID);
        world.setBlock(i + 9, j + 2, k + 7, Block.stone.blockID);
        world.setBlock(i + 9, j + 2, k + 8, Block.stone.blockID);
        world.setBlock(i + 9, j + 2, k + 9, Block.stone.blockID);
        world.setBlock(i + 9, j + 2, k + 10, Block.stone.blockID);
        world.setBlock(i + 9, j + 2, k + 11, Block.stone.blockID);
        world.setBlock(i + 9, j + 2, k + 12, Block.stone.blockID);
        world.setBlock(i + 9, j + 2, k + 13, Block.stone.blockID);
        world.setBlock(i + 9, j + 3, k + 1, Block.stone.blockID);
        world.setBlock(i + 9, j + 3, k + 13, Block.chest.blockID, 2, 0);
        world.setBlock(i + 9, j + 3, k + 14, Block.stone.blockID);
        world.setBlock(i + 9, j + 4, k + 1, Block.glass.blockID);
        world.setBlock(i + 9, j + 4, k + 14, Block.glass.blockID);
        world.setBlock(i + 9, j + 5, k + 1, Block.glass.blockID);
        world.setBlock(i + 9, j + 5, k + 14, Block.glass.blockID);
        world.setBlock(i + 9, j + 6, k + 1, Block.stone.blockID);
        world.setBlock(i + 9, j + 6, k + 2, Block.planks.blockID);
        world.setBlock(i + 9, j + 6, k + 14, Block.stone.blockID);
        world.setBlock(i + 9, j + 7, k + 1, Block.glass.blockID);
        world.setBlock(i + 9, j + 7, k + 2, Block.blockLapis.blockID);
        world.setBlock(i + 9, j + 7, k + 3, Block.stone.blockID);
        world.setBlock(i + 9, j + 7, k + 4, Block.glowStone.blockID);
        world.setBlock(i + 9, j + 7, k + 5, Block.stone.blockID);
        world.setBlock(i + 9, j + 7, k + 6, Block.stone.blockID);
        world.setBlock(i + 9, j + 7, k + 7, Block.glass.blockID);
        world.setBlock(i + 9, j + 7, k + 8, Block.stone.blockID);
        world.setBlock(i + 9, j + 7, k + 9, Block.stone.blockID);
        world.setBlock(i + 9, j + 7, k + 10, Block.glowStone.blockID);
        world.setBlock(i + 9, j + 7, k + 11, Block.stone.blockID);
        world.setBlock(i + 9, j + 7, k + 12, Block.stone.blockID);
        world.setBlock(i + 9, j + 7, k + 13, Block.glass.blockID);
        world.setBlock(i + 9, j + 8, k + 2, Block.glass.blockID);
        world.setBlock(i + 9, j + 8, k + 4, Block.stone.blockID);
        world.setBlock(i + 9, j + 8, k + 10, Block.stone.blockID);
        world.setBlock(i + 10, j + 0, k + 4, Block.stone.blockID);
        world.setBlock(i + 10, j + 0, k + 5, Block.stone.blockID);
        world.setBlock(i + 10, j + 0, k + 11, Block.stone.blockID);
        world.setBlock(i + 10, j + 0, k + 12, Block.stone.blockID);
        world.setBlock(i + 10, j + 1, k + 3, Block.stone.blockID);
        world.setBlock(i + 10, j + 1, k + 4, Block.stone.blockID);
        world.setBlock(i + 10, j + 1, k + 5, Block.stone.blockID);
        world.setBlock(i + 10, j + 1, k + 6, Block.stone.blockID);
        world.setBlock(i + 10, j + 1, k + 7, Block.stone.blockID);
        world.setBlock(i + 10, j + 1, k + 8, Block.stone.blockID);
        world.setBlock(i + 10, j + 1, k + 9, Block.stone.blockID);
        world.setBlock(i + 10, j + 1, k + 10, Block.stone.blockID);
        world.setBlock(i + 10, j + 1, k + 11, Block.stone.blockID);
        world.setBlock(i + 10, j + 1, k + 12, Block.stone.blockID);
        world.setBlock(i + 10, j + 2, k + 1, Block.stone.blockID);
        world.setBlock(i + 10, j + 2, k + 4, Block.stone.blockID);
        world.setBlock(i + 10, j + 2, k + 5, Block.stone.blockID);
        world.setBlock(i + 10, j + 2, k + 6, Block.stone.blockID);
        world.setBlock(i + 10, j + 2, k + 7, Block.stone.blockID);
        world.setBlock(i + 10, j + 2, k + 8, Block.stone.blockID);
        world.setBlock(i + 10, j + 2, k + 9, Block.stone.blockID);
        world.setBlock(i + 10, j + 2, k + 10, Block.stone.blockID);
        world.setBlock(i + 10, j + 2, k + 11, Block.stone.blockID);
        world.setBlock(i + 10, j + 2, k + 12, Block.stone.blockID);
        world.setBlock(i + 10, j + 2, k + 13, Block.stone.blockID);
        world.setBlock(i + 10, j + 3, k + 1, Block.stone.blockID);
        world.setBlock(i + 10, j + 3, k + 13, Block.chest.blockID, 2, 0);
        world.setBlock(i + 10, j + 3, k + 14, Block.stone.blockID);
        world.setBlock(i + 10, j + 4, k + 1, Block.stone.blockID);
        world.setBlock(i + 10, j + 4, k + 14, Block.stone.blockID);
        world.setBlock(i + 10, j + 5, k + 1, Block.stone.blockID);
        world.setBlock(i + 10, j + 5, k + 2, Block.dispenser.blockID, 3, 0);
        world.setBlock(i + 10, j + 5, k + 14, Block.stone.blockID);
        world.setBlock(i + 10, j + 6, k + 1, Block.stone.blockID);
        world.setBlock(i + 10, j + 6, k + 2, Block.planks.blockID);
        world.setBlock(i + 10, j + 6, k + 14, Block.stone.blockID);
        world.setBlock(i + 10, j + 7, k + 1, Block.stone.blockID);
        world.setBlock(i + 10, j + 7, k + 2, Block.blockLapis.blockID);
        world.setBlock(i + 10, j + 7, k + 3, Block.glowStone.blockID);
        world.setBlock(i + 10, j + 7, k + 4, Block.stone.blockID);
        world.setBlock(i + 10, j + 7, k + 5, Block.stone.blockID);
        world.setBlock(i + 10, j + 7, k + 6, Block.glass.blockID);
        world.setBlock(i + 10, j + 7, k + 7, Block.glass.blockID);
        world.setBlock(i + 10, j + 7, k + 8, Block.glass.blockID);
        world.setBlock(i + 10, j + 7, k + 9, Block.stone.blockID);
        world.setBlock(i + 10, j + 7, k + 10, Block.stone.blockID);
        world.setBlock(i + 10, j + 7, k + 11, Block.glowStone.blockID);
        world.setBlock(i + 10, j + 7, k + 12, Block.stone.blockID);
        world.setBlock(i + 10, j + 7, k + 13, Block.stone.blockID);
        world.setBlock(i + 10, j + 7, k + 14, Block.stone.blockID);
        world.setBlock(i + 10, j + 8, k + 2, Block.glass.blockID);
        world.setBlock(i + 10, j + 8, k + 3, Block.stone.blockID);
        world.setBlock(i + 10, j + 8, k + 11, Block.stone.blockID);
        world.setBlock(i + 11, j + 0, k + 2, Block.stone.blockID);
        world.setBlock(i + 11, j + 0, k + 3, Block.stone.blockID);
        world.setBlock(i + 11, j + 0, k + 4, Block.stone.blockID);
        world.setBlock(i + 11, j + 0, k + 12, Block.stone.blockID);
        world.setBlock(i + 11, j + 0, k + 13, Block.stone.blockID);
        world.setBlock(i + 11, j + 1, k + 2, Block.stone.blockID);
        world.setBlock(i + 11, j + 1, k + 3, Block.stone.blockID);
        world.setBlock(i + 11, j + 1, k + 4, Block.stone.blockID);
        world.setBlock(i + 11, j + 1, k + 5, Block.stone.blockID);
        world.setBlock(i + 11, j + 1, k + 6, Block.stone.blockID);
        world.setBlock(i + 11, j + 1, k + 7, Block.stone.blockID);
        world.setBlock(i + 11, j + 1, k + 8, Block.stone.blockID);
        world.setBlock(i + 11, j + 1, k + 9, Block.stone.blockID);
        world.setBlock(i + 11, j + 1, k + 10, Block.stone.blockID);
        world.setBlock(i + 11, j + 1, k + 11, Block.stone.blockID);
        world.setBlock(i + 11, j + 1, k + 12, Block.stone.blockID);
        world.setBlock(i + 11, j + 1, k + 13, Block.stone.blockID);
        world.setBlock(i + 11, j + 2, k + 2, Block.stone.blockID);
        world.setBlock(i + 11, j + 2, k + 3, Block.stone.blockID);
        world.setBlock(i + 11, j + 2, k + 4, Block.stone.blockID);
        world.setBlock(i + 11, j + 2, k + 5, Block.stone.blockID);
        world.setBlock(i + 11, j + 2, k + 6, Block.stone.blockID);
        world.setBlock(i + 11, j + 2, k + 7, Block.stone.blockID);
        world.setBlock(i + 11, j + 2, k + 8, Block.stone.blockID);
        world.setBlock(i + 11, j + 2, k + 9, Block.stone.blockID);
        world.setBlock(i + 11, j + 2, k + 10, Block.stone.blockID);
        world.setBlock(i + 11, j + 2, k + 11, Block.stone.blockID);
        world.setBlock(i + 11, j + 2, k + 12, Block.stone.blockID);
        world.setBlock(i + 11, j + 2, k + 13, Block.stone.blockID);
        world.setBlock(i + 11, j + 3, k + 2, Block.stone.blockID);
        world.setBlock(i + 11, j + 3, k + 13, Block.stone.blockID);
        world.setBlock(i + 11, j + 4, k + 2, Block.stone.blockID);
        world.setBlock(i + 11, j + 4, k + 13, Block.stone.blockID);
        world.setBlock(i + 11, j + 5, k + 2, Block.stone.blockID);
        world.setBlock(i + 11, j + 5, k + 13, Block.stone.blockID);
        world.setBlock(i + 11, j + 6, k + 2, Block.stone.blockID);
        world.setBlock(i + 11, j + 6, k + 13, Block.stone.blockID);
        world.setBlock(i + 11, j + 7, k + 2, Block.stone.blockID);
        world.setBlock(i + 11, j + 7, k + 3, Block.stone.blockID);
        world.setBlock(i + 11, j + 7, k + 4, Block.stone.blockID);
        world.setBlock(i + 11, j + 7, k + 5, Block.glass.blockID);
        world.setBlock(i + 11, j + 7, k + 6, Block.glass.blockID);
        world.setBlock(i + 11, j + 7, k + 7, Block.glass.blockID);
        world.setBlock(i + 11, j + 7, k + 8, Block.glass.blockID);
        world.setBlock(i + 11, j + 7, k + 9, Block.glass.blockID);
        world.setBlock(i + 11, j + 7, k + 10, Block.stone.blockID);
        world.setBlock(i + 11, j + 7, k + 11, Block.stone.blockID);
        world.setBlock(i + 11, j + 7, k + 12, Block.stone.blockID);
        world.setBlock(i + 11, j + 7, k + 13, Block.stone.blockID);
        world.setBlock(i + 12, j + 0, k + 3, Block.stone.blockID);
        world.setBlock(i + 12, j + 0, k + 12, Block.stone.blockID);
        world.setBlock(i + 12, j + 1, k + 3, Block.stone.blockID);
        world.setBlock(i + 12, j + 1, k + 12, Block.stone.blockID);
        world.setBlock(i + 12, j + 2, k + 3, Block.stone.blockID);
        world.setBlock(i + 12, j + 2, k + 4, Block.stone.blockID);
        world.setBlock(i + 12, j + 2, k + 5, Block.stone.blockID);
        world.setBlock(i + 12, j + 2, k + 6, Block.stone.blockID);
        world.setBlock(i + 12, j + 2, k + 7, Block.dirt.blockID);
        world.setBlock(i + 12, j + 2, k + 8, Block.dirt.blockID);
        world.setBlock(i + 12, j + 2, k + 9, Block.stone.blockID);
        world.setBlock(i + 12, j + 2, k + 10, Block.stone.blockID);
        world.setBlock(i + 12, j + 2, k + 11, Block.stone.blockID);
        world.setBlock(i + 12, j + 2, k + 12, Block.stone.blockID);
        world.setBlock(i + 12, j + 3, k + 3, Block.stone.blockID);
        world.setBlock(i + 12, j + 3, k + 4, Block.stone.blockID);
        world.setBlock(i + 12, j + 3, k + 5, Block.stone.blockID);
        world.setBlock(i + 12, j + 3, k + 10, Block.stone.blockID);
        world.setBlock(i + 12, j + 3, k + 11, Block.stone.blockID);
        world.setBlock(i + 12, j + 3, k + 12, Block.stone.blockID);
        world.setBlock(i + 12, j + 4, k + 3, Block.stone.blockID);
        world.setBlock(i + 12, j + 4, k + 4, Block.stone.blockID);
        world.setBlock(i + 12, j + 4, k + 5, Block.stone.blockID);
        world.setBlock(i + 12, j + 4, k + 10, Block.stone.blockID);
        world.setBlock(i + 12, j + 4, k + 11, Block.stone.blockID);
        world.setBlock(i + 12, j + 4, k + 12, Block.stone.blockID);
        world.setBlock(i + 12, j + 5, k + 3, Block.stone.blockID);
        world.setBlock(i + 12, j + 5, k + 4, Block.glass.blockID);
        world.setBlock(i + 12, j + 5, k + 5, Block.stone.blockID);
        world.setBlock(i + 12, j + 5, k + 6, Block.stone.blockID);
        world.setBlock(i + 12, j + 5, k + 9, Block.stone.blockID);
        world.setBlock(i + 12, j + 5, k + 10, Block.stone.blockID);
        world.setBlock(i + 12, j + 5, k + 11, Block.glass.blockID);
        world.setBlock(i + 12, j + 5, k + 12, Block.stone.blockID);
        world.setBlock(i + 12, j + 6, k + 3, Block.stone.blockID);
        world.setBlock(i + 12, j + 6, k + 4, Block.glass.blockID);
        world.setBlock(i + 12, j + 6, k + 5, Block.glass.blockID);
        world.setBlock(i + 12, j + 6, k + 6, Block.stone.blockID);
        world.setBlock(i + 12, j + 6, k + 7, Block.stone.blockID);
        world.setBlock(i + 12, j + 6, k + 8, Block.stone.blockID);
        world.setBlock(i + 12, j + 6, k + 9, Block.stone.blockID);
        world.setBlock(i + 12, j + 6, k + 10, Block.glass.blockID);
        world.setBlock(i + 12, j + 6, k + 11, Block.glass.blockID);
        world.setBlock(i + 12, j + 6, k + 12, Block.stone.blockID);
        world.setBlock(i + 12, j + 7, k + 3, Block.stone.blockID);
        world.setBlock(i + 12, j + 7, k + 12, Block.stone.blockID);

		return true;    
        }
}
